2025-01-16 11:41:38,472 - 15214 - browsergym.experiments.loop - INFO - Running experiment DemoAgentArgs_on_workarena.servicenow.order-apple-mac-book-pro15_28 in:
  results/2025-01-16_11-41-38_DemoAgentArgs_on_workarena.servicenow.order-apple-mac-book-pro15_28
2025-01-16 11:41:38,852 - 15214 - browsergym.experiments.loop - WARNING - Exception uncaught by agent or environment in task workarena.servicenow.order-apple-mac-book-pro15.
RuntimeError:
ServiceNow instance at https://dev182361.service-now.com is not reachable. Please check the URL.
Traceback (most recent call last):
  File "/Volumes/8TB-Files/backup level 1/Dropbox/PARA/20_code/2024-12-09_WorkBench/BrowserGym_n/.venv/lib/python3.12/site-packages/urllib3/connection.py", line 199, in _new_conn
    sock = connection.create_connection(
           ^^^^^^^^^^^^^^^^^^^^^^^^^^^^^
  File "/Volumes/8TB-Files/backup level 1/Dropbox/PARA/20_code/2024-12-09_WorkBench/BrowserGym_n/.venv/lib/python3.12/site-packages/urllib3/util/connection.py", line 85, in create_connection
    raise err
  File "/Volumes/8TB-Files/backup level 1/Dropbox/PARA/20_code/2024-12-09_WorkBench/BrowserGym_n/.venv/lib/python3.12/site-packages/urllib3/util/connection.py", line 73, in create_connection
    sock.connect(sa)
ConnectionRefusedError: [Errno 61] Connection refused

The above exception was the direct cause of the following exception:

Traceback (most recent call last):
  File "/Volumes/8TB-Files/backup level 1/Dropbox/PARA/20_code/2024-12-09_WorkBench/BrowserGym_n/.venv/lib/python3.12/site-packages/urllib3/connectionpool.py", line 789, in urlopen
    response = self._make_request(
               ^^^^^^^^^^^^^^^^^^^
  File "/Volumes/8TB-Files/backup level 1/Dropbox/PARA/20_code/2024-12-09_WorkBench/BrowserGym_n/.venv/lib/python3.12/site-packages/urllib3/connectionpool.py", line 490, in _make_request
    raise new_e
  File "/Volumes/8TB-Files/backup level 1/Dropbox/PARA/20_code/2024-12-09_WorkBench/BrowserGym_n/.venv/lib/python3.12/site-packages/urllib3/connectionpool.py", line 466, in _make_request
    self._validate_conn(conn)
  File "/Volumes/8TB-Files/backup level 1/Dropbox/PARA/20_code/2024-12-09_WorkBench/BrowserGym_n/.venv/lib/python3.12/site-packages/urllib3/connectionpool.py", line 1095, in _validate_conn
    conn.connect()
  File "/Volumes/8TB-Files/backup level 1/Dropbox/PARA/20_code/2024-12-09_WorkBench/BrowserGym_n/.venv/lib/python3.12/site-packages/urllib3/connection.py", line 693, in connect
    self.sock = sock = self._new_conn()
                       ^^^^^^^^^^^^^^^^
  File "/Volumes/8TB-Files/backup level 1/Dropbox/PARA/20_code/2024-12-09_WorkBench/BrowserGym_n/.venv/lib/python3.12/site-packages/urllib3/connection.py", line 214, in _new_conn
    raise NewConnectionError(
urllib3.exceptions.NewConnectionError: <urllib3.connection.HTTPSConnection object at 0x140b45460>: Failed to establish a new connection: [Errno 61] Connection refused

The above exception was the direct cause of the following exception:

Traceback (most recent call last):
  File "/Volumes/8TB-Files/backup level 1/Dropbox/PARA/20_code/2024-12-09_WorkBench/BrowserGym_n/.venv/lib/python3.12/site-packages/requests/adapters.py", line 667, in send
    resp = conn.urlopen(
           ^^^^^^^^^^^^^
  File "/Volumes/8TB-Files/backup level 1/Dropbox/PARA/20_code/2024-12-09_WorkBench/BrowserGym_n/.venv/lib/python3.12/site-packages/urllib3/connectionpool.py", line 843, in urlopen
    retries = retries.increment(
              ^^^^^^^^^^^^^^^^^^
  File "/Volumes/8TB-Files/backup level 1/Dropbox/PARA/20_code/2024-12-09_WorkBench/BrowserGym_n/.venv/lib/python3.12/site-packages/urllib3/util/retry.py", line 519, in increment
    raise MaxRetryError(_pool, url, reason) from reason  # type: ignore[arg-type]
    ^^^^^^^^^^^^^^^^^^^^^^^^^^^^^^^^^^^^^^^^^^^^^^^^^^^
urllib3.exceptions.MaxRetryError: HTTPSConnectionPool(host='dev182361.service-now.com', port=443): Max retries exceeded with url: / (Caused by NewConnectionError('<urllib3.connection.HTTPSConnection object at 0x140b45460>: Failed to establish a new connection: [Errno 61] Connection refused'))

During handling of the above exception, another exception occurred:

Traceback (most recent call last):
  File "/Volumes/8TB-Files/backup level 1/Dropbox/PARA/20_code/2024-12-09_WorkBench/BrowserGym_n/.venv/lib/python3.12/site-packages/browsergym/workarena/instance.py", line 86, in _check_is_reachable
    requests.get(self.snow_url, timeout=SNOW_BROWSER_TIMEOUT)
  File "/Volumes/8TB-Files/backup level 1/Dropbox/PARA/20_code/2024-12-09_WorkBench/BrowserGym_n/.venv/lib/python3.12/site-packages/requests/api.py", line 73, in get
    return request("get", url, params=params, **kwargs)
           ^^^^^^^^^^^^^^^^^^^^^^^^^^^^^^^^^^^^^^^^^^^^
  File "/Volumes/8TB-Files/backup level 1/Dropbox/PARA/20_code/2024-12-09_WorkBench/BrowserGym_n/.venv/lib/python3.12/site-packages/requests/api.py", line 59, in request
    return session.request(method=method, url=url, **kwargs)
           ^^^^^^^^^^^^^^^^^^^^^^^^^^^^^^^^^^^^^^^^^^^^^^^^^
  File "/Volumes/8TB-Files/backup level 1/Dropbox/PARA/20_code/2024-12-09_WorkBench/BrowserGym_n/.venv/lib/python3.12/site-packages/requests/sessions.py", line 589, in request
    resp = self.send(prep, **send_kwargs)
           ^^^^^^^^^^^^^^^^^^^^^^^^^^^^^^
  File "/Volumes/8TB-Files/backup level 1/Dropbox/PARA/20_code/2024-12-09_WorkBench/BrowserGym_n/.venv/lib/python3.12/site-packages/requests/sessions.py", line 703, in send
    r = adapter.send(request, **kwargs)
        ^^^^^^^^^^^^^^^^^^^^^^^^^^^^^^^
  File "/Volumes/8TB-Files/backup level 1/Dropbox/PARA/20_code/2024-12-09_WorkBench/BrowserGym_n/.venv/lib/python3.12/site-packages/requests/adapters.py", line 700, in send
    raise ConnectionError(e, request=request)
requests.exceptions.ConnectionError: HTTPSConnectionPool(host='dev182361.service-now.com', port=443): Max retries exceeded with url: / (Caused by NewConnectionError('<urllib3.connection.HTTPSConnection object at 0x140b45460>: Failed to establish a new connection: [Errno 61] Connection refused'))

During handling of the above exception, another exception occurred:

Traceback (most recent call last):
  File "/Volumes/8TB-Files/backup level 1/Dropbox/PARA/20_code/2024-12-09_WorkBench/BrowserGym_n/.venv/lib/python3.12/site-packages/browsergym/experiments/loop.py", line 246, in run
    step_info.from_reset(
  File "/Volumes/8TB-Files/backup level 1/Dropbox/PARA/20_code/2024-12-09_WorkBench/BrowserGym_n/.venv/lib/python3.12/site-packages/browsergym/experiments/loop.py", line 437, in from_reset
    self.obs, env_info = env.reset(seed=seed)
                         ^^^^^^^^^^^^^^^^^^^^
  File "/Volumes/8TB-Files/backup level 1/Dropbox/PARA/20_code/2024-12-09_WorkBench/BrowserGym_n/.venv/lib/python3.12/site-packages/gymnasium/wrappers/common.py", line 146, in reset
    return super().reset(seed=seed, options=options)
           ^^^^^^^^^^^^^^^^^^^^^^^^^^^^^^^^^^^^^^^^^
  File "/Volumes/8TB-Files/backup level 1/Dropbox/PARA/20_code/2024-12-09_WorkBench/BrowserGym_n/.venv/lib/python3.12/site-packages/gymnasium/core.py", line 328, in reset
    return self.env.reset(seed=seed, options=options)
           ^^^^^^^^^^^^^^^^^^^^^^^^^^^^^^^^^^^^^^^^^^
  File "/Volumes/8TB-Files/backup level 1/Dropbox/PARA/20_code/2024-12-09_WorkBench/BrowserGym_n/.venv/lib/python3.12/site-packages/gymnasium/wrappers/common.py", line 400, in reset
    return super().reset(seed=seed, options=options)
           ^^^^^^^^^^^^^^^^^^^^^^^^^^^^^^^^^^^^^^^^^
  File "/Volumes/8TB-Files/backup level 1/Dropbox/PARA/20_code/2024-12-09_WorkBench/BrowserGym_n/.venv/lib/python3.12/site-packages/gymnasium/core.py", line 328, in reset
    return self.env.reset(seed=seed, options=options)
           ^^^^^^^^^^^^^^^^^^^^^^^^^^^^^^^^^^^^^^^^^^
  File "/Volumes/8TB-Files/backup level 1/Dropbox/PARA/20_code/2024-12-09_WorkBench/BrowserGym_n/.venv/lib/python3.12/site-packages/browsergym/core/env.py", line 204, in reset
    self.task = self.task_entrypoint(seed=seed, **self.task_kwargs)
                ^^^^^^^^^^^^^^^^^^^^^^^^^^^^^^^^^^^^^^^^^^^^^^^^^^^
  File "/Volumes/8TB-Files/backup level 1/Dropbox/PARA/20_code/2024-12-09_WorkBench/BrowserGym_n/.venv/lib/python3.12/site-packages/browsergym/core/registration.py", line 28, in __call__
    return self.func(*args, **kwargs)
           ^^^^^^^^^^^^^^^^^^^^^^^^^^
  File "/Volumes/8TB-Files/backup level 1/Dropbox/PARA/20_code/2024-12-09_WorkBench/BrowserGym_n/.venv/lib/python3.12/site-packages/browsergym/workarena/tasks/service_catalog.py", line 641, in __init__
    super().__init__(
  File "/Volumes/8TB-Files/backup level 1/Dropbox/PARA/20_code/2024-12-09_WorkBench/BrowserGym_n/.venv/lib/python3.12/site-packages/browsergym/workarena/tasks/service_catalog.py", line 177, in __init__
    super().__init__(
  File "/Volumes/8TB-Files/backup level 1/Dropbox/PARA/20_code/2024-12-09_WorkBench/BrowserGym_n/.venv/lib/python3.12/site-packages/browsergym/workarena/tasks/base.py", line 66, in __init__
    self.instance = instance if instance is not None else SNowInstance()
                                                          ^^^^^^^^^^^^^^
  File "/Volumes/8TB-Files/backup level 1/Dropbox/PARA/20_code/2024-12-09_WorkBench/BrowserGym_n/.venv/lib/python3.12/site-packages/browsergym/workarena/instance.py", line 57, in __init__
    self.check_status()
  File "/Volumes/8TB-Files/backup level 1/Dropbox/PARA/20_code/2024-12-09_WorkBench/BrowserGym_n/.venv/lib/python3.12/site-packages/browsergym/workarena/instance.py", line 64, in check_status
    self._check_is_reachable()
  File "/Volumes/8TB-Files/backup level 1/Dropbox/PARA/20_code/2024-12-09_WorkBench/BrowserGym_n/.venv/lib/python3.12/site-packages/browsergym/workarena/instance.py", line 88, in _check_is_reachable
    raise RuntimeError(
RuntimeError: ServiceNow instance at https://dev182361.service-now.com is not reachable. Please check the URL.

2025-01-16 11:41:38,852 - 15214 - browsergym.experiments.loop - INFO - Saving summary info.
